Workbook
Name IT_Sectors: '00 COMMON - Run Setup'!$AA$5
Name OT_Sectors: '00 COMMON - Run Setup'!$AB$5:$AB$7
Name Financial_Services: '00 COMMON - Run Setup'!$Z$8
Name Power_Generation: 'OT PACK - Loaded Registry'!$B$25:$B$30
Name Energy_Assets: 'OT PACK - Loaded Registry'!$B$31:$B$35
Name Manufacturing: 'OT PACK - Loaded Registry'!$B$36:$B$39

Sheet 1 Executive dashboards
A1: 1 Executive dashboards
A3: Read after python -m crq run. Do not enter assessment data here.

Sheet 01 Executive Risk Story

Sheet 02 Risk Formation

Sheet 03 Scenario Analysis

Sheet 04 Business Impact

Sheet 05 Risk Treatment

Sheet 06 Appetite & Insurance
A1: 06 — Appetite & Insurance
A2: Risk-appetite thresholds are organisational policy inputs. Insurance programme terms are risk-financing inputs — not pricing.
A4: RISK APPETITE INPUTS (optional — leave blank if unset)
A5: Parameter | B5: Value
A6: ANNUAL_LOSS_TOLERANCE | C6: Annual aggregate loss tolerance ($)
A7: MAX_ACCEPTABLE_EVENT_PROBABILITY | C7: Max acceptable annual event probability
A8: MAX_ACCEPTABLE_TVAR_95 | C8: Max acceptable TVaR 95 ($)
A9: MAX_ACCEPTABLE_TVAR_99 | C9: Max acceptable TVaR 99 ($)
A10: MAX_ACCEPTABLE_DOWNTIME_DAYS | C10: Max acceptable downtime P95 (days)
A12: INSURANCE PROGRAMME INPUTS (risk-financing — not pricing)
A13: INSURANCE_RETENTION | B13: 0
A14: PRIMARY_LIMIT
A15: AGGREGATE_PROGRAMME_LIMIT
A17: Layer | B17: Attachment | C17: Limit | D17: Coinsurance
A18: Primary | D18: 1
A19: Excess 1 | D19: 1
A20: INSURANCE PROGRAMME INPUTS | D20: 1
A21: Excess 3 | D21: 1

Sheet 07 Uncertainty & Evidence

Sheet 00 Dashboard
A1: IT / OT CYBER RISK QUANTIFICATION | EXECUTIVE DASHBOARD
A2: Common decision view. The selected sector determines the governed calculation engine; dashboard metrics read the normalized output bridge.
A4: Sector | B4: ='00 COMMON - Output Bridge'!B6 | C4: Domain | D4: ='00 COMMON - Output Bridge'!B7 | E4: Pack | F4: ='00 COMMON - Output Bridge'!B9 | G4: Basis | H4: =IF('00 COMMON - Run Setup'!C6="IT",'IT 08 - Reporting Settings'!B16,'00 COMMON - Run Setup'!C9) | I4: Outside-in | J4: ='00 COMMON - Run Setup'!C10 | K4: Asset / scope | L4: ='00 COMMON - Output Bridge'!B8
A7: ANNUAL AVERAGE LOSS | D7: TVaR 95% | G7: TVaR 99% | J7: P(ANY SUCCESSFUL EVENT) | M7: CAMPAIGNS / YEAR
A8: =IF('00 COMMON - Run Setup'!C9="Best Estimate",'00 COMMON - Output Bridge'!B15,'00 COMMON - Output Bridge'!C15) | D8: =IF('00 COMMON - Run Setup'!C9="Best Estimate",'00 COMMON - Output Bridge'!B17,'00 COMMON - Output Bridge'!C17) | G8: =IF('00 COMMON - Run Setup'!C9="Best Estimate",'00 COMMON - Output Bridge'!B19,'00 COMMON - Output Bridge'!C19) | J8: =IF('00 COMMON - Run Setup'!C9="Best Estimate",'00 COMMON - Output Bridge'!B20,'00 COMMON - Output Bridge'!C20) | M8: =IF('00 COMMON - Run Setup'!C9="Best Estimate",'00 COMMON - Output Bridge'!B21,'00 COMMON - Output Bridge'!C21)
A12: AGGREGATE LOSS EXCEEDANCE
A13: Exceedance probability | B13: AEP | C13: OEP
A14: ='00 COMMON - Output Bridge'!A43 | B14: =IF('00 COMMON - Run Setup'!C9="Best Estimate",'00 COMMON - Output Bridge'!B43,'00 COMMON - Output Bridge'!D43) | C14: =IF('00 COMMON - Run Setup'!C9="Best Estimate",'00 COMMON - Output Bridge'!C43,'00 COMMON - Output Bridge'!E43)
A15: ='00 COMMON - Output Bridge'!A44 | B15: =IF('00 COMMON - Run Setup'!C9="Best Estimate",'00 COMMON - Output Bridge'!B44,'00 COMMON - Output Bridge'!D44) | C15: =IF('00 COMMON - Run Setup'!C9="Best Estimate",'00 COMMON - Output Bridge'!C44,'00 COMMON - Output Bridge'!E44)
A16: ='00 COMMON - Output Bridge'!A45 | B16: =IF('00 COMMON - Run Setup'!C9="Best Estimate",'00 COMMON - Output Bridge'!B45,'00 COMMON - Output Bridge'!D45) | C16: =IF('00 COMMON - Run Setup'!C9="Best Estimate",'00 COMMON - Output Bridge'!C45,'00 COMMON - Output Bridge'!E45)
A17: ='00 COMMON - Output Bridge'!A46 | B17: =IF('00 COMMON - Run Setup'!C9="Best Estimate",'00 COMMON - Output Bridge'!B46,'00 COMMON - Output Bridge'!D46) | C17: =IF('00 COMMON - Run Setup'!C9="Best Estimate",'00 COMMON - Output Bridge'!C46,'00 COMMON - Output Bridge'!E46)
A18: ='00 COMMON - Output Bridge'!A47 | B18: =IF('00 COMMON - Run Setup'!C9="Best Estimate",'00 COMMON - Output Bridge'!B47,'00 COMMON - Output Bridge'!D47) | C18: =IF('00 COMMON - Run Setup'!C9="Best Estimate",'00 COMMON - Output Bridge'!C47,'00 COMMON - Output Bridge'!E47)
A19: ='00 COMMON - Output Bridge'!A48 | B19: =IF('00 COMMON - Run Setup'!C9="Best Estimate",'00 COMMON - Output Bridge'!B48,'00 COMMON - Output Bridge'!D48) | C19: =IF('00 COMMON - Run Setup'!C9="Best Estimate",'00 COMMON - Output Bridge'!C48,'00 COMMON - Output Bridge'!E48)
A20: ='00 COMMON - Output Bridge'!A49 | B20: =IF('00 COMMON - Run Setup'!C9="Best Estimate",'00 COMMON - Output Bridge'!B49,'00 COMMON - Output Bridge'!D49) | C20: =IF('00 COMMON - Run Setup'!C9="Best Estimate",'00 COMMON - Output Bridge'!C49,'00 COMMON - Output Bridge'!E49)
A21: ='00 COMMON - Output Bridge'!A50 | B21: =IF('00 COMMON - Run Setup'!C9="Best Estimate",'00 COMMON - Output Bridge'!B50,'00 COMMON - Output Bridge'!D50) | C21: =IF('00 COMMON - Run Setup'!C9="Best Estimate",'00 COMMON - Output Bridge'!C50,'00 COMMON - Output Bridge'!E50)
A22: ='00 COMMON - Output Bridge'!A51 | B22: =IF('00 COMMON - Run Setup'!C9="Best Estimate",'00 COMMON - Output Bridge'!B51,'00 COMMON - Output Bridge'!D51) | C22: =IF('00 COMMON - Run Setup'!C9="Best Estimate",'00 COMMON - Output Bridge'!C51,'00 COMMON - Output Bridge'!E51)
A23: ='00 COMMON - Output Bridge'!A52 | B23: =IF('00 COMMON - Run Setup'!C9="Best Estimate",'00 COMMON - Output Bridge'!B52,'00 COMMON - Output Bridge'!D52) | C23: =IF('00 COMMON - Run Setup'!C9="Best Estimate",'00 COMMON - Output Bridge'!C52,'00 COMMON - Output Bridge'!E52)
A24: ='00 COMMON - Output Bridge'!A53 | B24: =IF('00 COMMON - Run Setup'!C9="Best Estimate",'00 COMMON - Output Bridge'!B53,'00 COMMON - Output Bridge'!D53) | C24: =IF('00 COMMON - Run Setup'!C9="Best Estimate",'00 COMMON - Output Bridge'!C53,'00 COMMON - Output Bridge'!E53)
A29: RISK CONCENTRATION
A30: Threat actor | B30: AAL | I30: Scenario | J30: AAL
A31: ='00 COMMON - Output Bridge'!A27 | B31: ='00 COMMON - Output Bridge'!B27 | I31: ='00 COMMON - Output Bridge'!A34 | J31: ='00 COMMON - Output Bridge'!B34
A32: ='00 COMMON - Output Bridge'!A28 | B32: ='00 COMMON - Output Bridge'!B28 | I32: ='00 COMMON - Output Bridge'!A35 | J32: ='00 COMMON - Output Bridge'!B35
A33: ='00 COMMON - Output Bridge'!A29 | B33: ='00 COMMON - Output Bridge'!B29 | I33: ='00 COMMON - Output Bridge'!A36 | J33: ='00 COMMON - Output Bridge'!B36
A34: ='00 COMMON - Output Bridge'!A30 | B34: ='00 COMMON - Output Bridge'!B30 | I34: ='00 COMMON - Output Bridge'!A37 | J34: ='00 COMMON - Output Bridge'!B37
I35: ='00 COMMON - Output Bridge'!A38 | J35: ='00 COMMON - Output Bridge'!B38
A46: OUTSIDE-IN CONDITIONING STATUS
A47: Scan applied? | B47: ='00 COMMON - Run Setup'!C10 | C47: Normalized file | D47: ='00 COMMON - Run Setup'!C11 | G47: Finding count | H47: ='00 COMMON - Outside-In'!B10 | I47: Quantitative adjustments | J47: ='00 COMMON - Outside-In'!B11 | K47: Baseline retained? | L47: =IF('00 COMMON - Run Setup'!C10="No","Yes","See rationale register")
A49: Interpretation | B49: No scan is a valid model state. When a scan is used, the final result must remain explainable through 00 OI Adjustment Rationale; no opaque scan-score multiplier is permitted.

Sheet 00 Risk Drivers
A1: IT / OT CYBER RISK QUANTIFICATION | RISK DRIVERS
A2: OT view: drill from actor/scenario into the five composite stages. For an IT run, the common runner should populate the normalized route/stage bridge using the IT route model rather than forcing OT stages.
A4: Threat actor | B4: Nation State | C4: Scenario | D4: Operational Disruption | E4: Detailed view | F4: Current engine output
A7: SELECTED ACTOR × SCENARIO
A8: Attempts / yr | B8: =IF('00 COMMON - Run Setup'!C6="OT",SUMIFS('OT CALC - Threat Frequency'!L16:L30,'OT CALC - Threat Frequency'!A16:A30,B4,'OT CALC - Threat Frequency'!B16:B30,D4),"") | C8: P(success) | D8: =IFERROR(IF('00 COMMON - Run Setup'!C6="OT",SUMIFS('OT CALC - Threat Frequency'!M16:M30,'OT CALC - Threat Frequency'!A16:A30,B4,'OT CALC - Threat Frequency'!B16:B30,D4),""),"") | E8: Successful events / yr | F8: =IF('00 COMMON - Run Setup'!C6="OT",SUMIFS('OT CALC - Threat Frequency'!N16:N30,'OT CALC - Threat Frequency'!A16:A30,B4,'OT CALC - Threat Frequency'!B16:B30,D4),"") | G8: AAL contribution | H8: =IF('00 COMMON - Run Setup'!C6="OT",INDEX('OT CALC - Actor-Scenario Matrix'!B16:F18,MATCH(B4,'OT CALC - Actor-Scenario Matrix'!A16:A18,0),MATCH(D4,'OT CALC - Actor-Scenario Matrix'!B15:F15,0)),"")
A12: COMPOSITE ATTACK-PATH STAGES
A13: Stage | B13: Required? | C13: Relevant TTPs | D13: Reference prior | E13: Actual barrier | F13: Through probability | G13: Interpretation
A14: S1 | B14: =IF('00 COMMON - Run Setup'!C6="OT",IF(COUNTIFS('OT CALC - Attack Path'!A16:A200,$B$4,'OT CALC - Attack Path'!B16:B200,$D$4,'OT CALC - Attack Path'!C16:C200,A14,'OT CALC - Attack Path'!D16:D200,"Yes")>0,"Yes","No"),"") | C14: =IF('00 COMMON - Run Setup'!C6="OT",SUMIFS('OT CALC - Attack Path'!E16:E200,'OT CALC - Attack Path'!A16:A200,$B$4,'OT CALC - Attack Path'!B16:B200,$D$4,'OT CALC - Attack Path'!C16:C200,A14),"") | D14: =IF('00 COMMON - Run Setup'!C6="OT",SUMIFS('OT CALC - Attack Path'!H16:H200,'OT CALC - Attack Path'!A16:A200,$B$4,'OT CALC - Attack Path'!B16:B200,$D$4,'OT CALC - Attack Path'!C16:C200,A14),"") | E14: =IF('00 COMMON - Run Setup'!C6="OT",SUMIFS('OT CALC - Attack Path'!J16:J200,'OT CALC - Attack Path'!A16:A200,$B$4,'OT CALC - Attack Path'!B16:B200,$D$4,'OT CALC - Attack Path'!C16:C200,A14),"") | F14: =IF('00 COMMON - Run Setup'!C6="OT",SUMIFS('OT CALC - Attack Path'!L16:L200,'OT CALC - Attack Path'!A16:A200,$B$4,'OT CALC - Attack Path'!B16:B200,$D$4,'OT CALC - Attack Path'!C16:C200,A14),"") | G14: Initial access
A15: S2 | B15: =IF('00 COMMON - Run Setup'!C6="OT",IF(COUNTIFS('OT CALC - Attack Path'!A16:A200,$B$4,'OT CALC - Attack Path'!B16:B200,$D$4,'OT CALC - Attack Path'!C16:C200,A15,'OT CALC - Attack Path'!D16:D200,"Yes")>0,"Yes","No"),"") | C15: =IF('00 COMMON - Run Setup'!C6="OT",SUMIFS('OT CALC - Attack Path'!E16:E200,'OT CALC - Attack Path'!A16:A200,$B$4,'OT CALC - Attack Path'!B16:B200,$D$4,'OT CALC - Attack Path'!C16:C200,A15),"") | D15: =IF('00 COMMON - Run Setup'!C6="OT",SUMIFS('OT CALC - Attack Path'!H16:H200,'OT CALC - Attack Path'!A16:A200,$B$4,'OT CALC - Attack Path'!B16:B200,$D$4,'OT CALC - Attack Path'!C16:C200,A15),"") | E15: =IF('00 COMMON - Run Setup'!C6="OT",SUMIFS('OT CALC - Attack Path'!J16:J200,'OT CALC - Attack Path'!A16:A200,$B$4,'OT CALC - Attack Path'!B16:B200,$D$4,'OT CALC - Attack Path'!C16:C200,A15),"") | F15: =IF('00 COMMON - Run Setup'!C6="OT",SUMIFS('OT CALC - Attack Path'!L16:L200,'OT CALC - Attack Path'!A16:A200,$B$4,'OT CALC - Attack Path'!B16:B200,$D$4,'OT CALC - Attack Path'!C16:C200,A15),"") | G15: Establish presence
A16: S3 | B16: =IF('00 COMMON - Run Setup'!C6="OT",IF(COUNTIFS('OT CALC - Attack Path'!A16:A200,$B$4,'OT CALC - Attack Path'!B16:B200,$D$4,'OT CALC - Attack Path'!C16:C200,A16,'OT CALC - Attack Path'!D16:D200,"Yes")>0,"Yes","No"),"") | C16: =IF('00 COMMON - Run Setup'!C6="OT",SUMIFS('OT CALC - Attack Path'!E16:E200,'OT CALC - Attack Path'!A16:A200,$B$4,'OT CALC - Attack Path'!B16:B200,$D$4,'OT CALC - Attack Path'!C16:C200,A16),"") | D16: =IF('00 COMMON - Run Setup'!C6="OT",SUMIFS('OT CALC - Attack Path'!H16:H200,'OT CALC - Attack Path'!A16:A200,$B$4,'OT CALC - Attack Path'!B16:B200,$D$4,'OT CALC - Attack Path'!C16:C200,A16),"") | E16: =IF('00 COMMON - Run Setup'!C6="OT",SUMIFS('OT CALC - Attack Path'!J16:J200,'OT CALC - Attack Path'!A16:A200,$B$4,'OT CALC - Attack Path'!B16:B200,$D$4,'OT CALC - Attack Path'!C16:C200,A16),"") | F16: =IF('00 COMMON - Run Setup'!C6="OT",SUMIFS('OT CALC - Attack Path'!L16:L200,'OT CALC - Attack Path'!A16:A200,$B$4,'OT CALC - Attack Path'!B16:B200,$D$4,'OT CALC - Attack Path'!C16:C200,A16),"") | G16: Move into OT
A17: S4 | B17: =IF('00 COMMON - Run Setup'!C6="OT",IF(COUNTIFS('OT CALC - Attack Path'!A16:A200,$B$4,'OT CALC - Attack Path'!B16:B200,$D$4,'OT CALC - Attack Path'!C16:C200,A17,'OT CALC - Attack Path'!D16:D200,"Yes")>0,"Yes","No"),"") | C17: =IF('00 COMMON - Run Setup'!C6="OT",SUMIFS('OT CALC - Attack Path'!E16:E200,'OT CALC - Attack Path'!A16:A200,$B$4,'OT CALC - Attack Path'!B16:B200,$D$4,'OT CALC - Attack Path'!C16:C200,A17),"") | D17: =IF('00 COMMON - Run Setup'!C6="OT",SUMIFS('OT CALC - Attack Path'!H16:H200,'OT CALC - Attack Path'!A16:A200,$B$4,'OT CALC - Attack Path'!B16:B200,$D$4,'OT CALC - Attack Path'!C16:C200,A17),"") | E17: =IF('00 COMMON - Run Setup'!C6="OT",SUMIFS('OT CALC - Attack Path'!J16:J200,'OT CALC - Attack Path'!A16:A200,$B$4,'OT CALC - Attack Path'!B16:B200,$D$4,'OT CALC - Attack Path'!C16:C200,A17),"") | F17: =IF('00 COMMON - Run Setup'!C6="OT",SUMIFS('OT CALC - Attack Path'!L16:L200,'OT CALC - Attack Path'!A16:A200,$B$4,'OT CALC - Attack Path'!B16:B200,$D$4,'OT CALC - Attack Path'!C16:C200,A17),"") | G17: Understand the process
A18: S5 | B18: =IF('00 COMMON - Run Setup'!C6="OT",IF(COUNTIFS('OT CALC - Attack Path'!A16:A200,$B$4,'OT CALC - Attack Path'!B16:B200,$D$4,'OT CALC - Attack Path'!C16:C200,A18,'OT CALC - Attack Path'!D16:D200,"Yes")>0,"Yes","No"),"") | C18: =IF('00 COMMON - Run Setup'!C6="OT",SUMIFS('OT CALC - Attack Path'!E16:E200,'OT CALC - Attack Path'!A16:A200,$B$4,'OT CALC - Attack Path'!B16:B200,$D$4,'OT CALC - Attack Path'!C16:C200,A18),"") | D18: =IF('00 COMMON - Run Setup'!C6="OT",SUMIFS('OT CALC - Attack Path'!H16:H200,'OT CALC - Attack Path'!A16:A200,$B$4,'OT CALC - Attack Path'!B16:B200,$D$4,'OT CALC - Attack Path'!C16:C200,A18),"") | E18: =IF('00 COMMON - Run Setup'!C6="OT",SUMIFS('OT CALC - Attack Path'!J16:J200,'OT CALC - Attack Path'!A16:A200,$B$4,'OT CALC - Attack Path'!B16:B200,$D$4,'OT CALC - Attack Path'!C16:C200,A18),"") | F18: =IF('00 COMMON - Run Setup'!C6="OT",SUMIFS('OT CALC - Attack Path'!L16:L200,'OT CALC - Attack Path'!A16:A200,$B$4,'OT CALC - Attack Path'!B16:B200,$D$4,'OT CALC - Attack Path'!C16:C200,A18),"") | G18: Achieve adverse outcome
A21: OUTSIDE-IN EVIDENCE LINK
A22: When applied, outside-in evidence should appear as a traceable change to an existing exposure/frequency input, a route-feasibility gate, or a relevant stage/barrier. Use 00 Outside-In for the observed evidence and 00 OI Adjustment Rationale for the baseline-to-conditioned bridge. Do not insert a scan score directly into AAL.

Sheet 00 Loss Analysis
A1: IT / OT CYBER RISK QUANTIFICATION | LOSS ANALYSIS
A2: Event-level consequence view. Outside-in evidence does not alter these financial impact assumptions solely because an external exposure is observed.
A4: Threat actor | B4: Nation State | C4: Scenario | D4: Operational Disruption | E4: Loss view | F4: P50 / P99
A7: SELECTED EVENT CONSEQUENCE
A8: Metric | B8: P50 | C8: P99 | D8: Meaning
A9: Downtime (days) | B9: =IF('00 COMMON - Run Setup'!C6="OT",SUMIFS('OT CALC - Consequence'!C16:C30,'OT CALC - Consequence'!A16:A30,$B$4,'OT CALC - Consequence'!B16:B30,$D$4),"") | C9: =IF('00 COMMON - Run Setup'!C6="OT",SUMIFS('OT CALC - Consequence'!D16:D30,'OT CALC - Consequence'!A16:A30,$B$4,'OT CALC - Consequence'!B16:B30,$D$4),"") | D9: Scenario/facility recovery duration
A10: Capacity affected | B10: =IF('00 COMMON - Run Setup'!C6="OT",SUMIFS('OT CALC - Consequence'!E16:E30,'OT CALC - Consequence'!A16:A30,$B$4,'OT CALC - Consequence'!B16:B30,$D$4),"") | C10: =IF('00 COMMON - Run Setup'!C6="OT",SUMIFS('OT CALC - Consequence'!F16:F30,'OT CALC - Consequence'!A16:A30,$B$4,'OT CALC - Consequence'!B16:B30,$D$4),"") | D10: Share of scoped capacity affected
A11: Total event loss | B11: =IF('00 COMMON - Run Setup'!C6="OT",SUMIFS('OT CALC - Consequence'!M16:M30,'OT CALC - Consequence'!A16:A30,$B$4,'OT CALC - Consequence'!B16:B30,$D$4),"") | C11: =IF('00 COMMON - Run Setup'!C6="OT",SUMIFS('OT CALC - Consequence'!N16:N30,'OT CALC - Consequence'!A16:A30,$B$4,'OT CALC - Consequence'!B16:B30,$D$4),"") | D11: Modelled BI + non-BI consequence
A14: BI / NON-BI DECOMPOSITION
A15: Component | B15: P50 | C15: P99
A16: Modelled BI | B16: =IF('00 COMMON - Run Setup'!C6="OT",SUMIFS('OT CALC - Consequence'!I16:I30,'OT CALC - Consequence'!A16:A30,$B$4,'OT CALC - Consequence'!B16:B30,$D$4),"") | C16: =IF('00 COMMON - Run Setup'!C6="OT",SUMIFS('OT CALC - Consequence'!J16:J30,'OT CALC - Consequence'!A16:A30,$B$4,'OT CALC - Consequence'!B16:B30,$D$4),"")
A17: Non-BI consequence | B17: =IF('00 COMMON - Run Setup'!C6="OT",SUMIFS('OT CALC - Consequence'!K16:K30,'OT CALC - Consequence'!A16:A30,$B$4,'OT CALC - Consequence'!B16:B30,$D$4),"") | C17: =IF('00 COMMON - Run Setup'!C6="OT",SUMIFS('OT CALC - Consequence'!L16:L30,'OT CALC - Consequence'!A16:A30,$B$4,'OT CALC - Consequence'!B16:B30,$D$4),"")
A32: OUTSIDE-IN BOUNDARY — Scan evidence can change likelihood because it provides evidence about external opportunity, exposed services, exploitable vulnerabilities or route feasibility. It does not independently evidence revenue-at-risk, restoration time, capacity affected, physical damage, safety, environmental loss or other consequence drivers.

Sheet 00 What-If
A1: IT / OT CYBER RISK QUANTIFICATION | CONTROL WHAT-IF
A2: Decision view of modelled control improvement. Engine-generated what-if values remain the system of record.
A4: Basis | B4: ='00 COMMON - Run Setup'!C9 | C4: Source | D4: 20 Control What-If
A7: CONTROL IMPROVEMENT RESULTS
A8: Control ID | B8: Control | C8: Channel | D8: Current maturity | E8: What-if maturity | F8: AAL reduction | G8: Reduction % | I8: Outside-in findings should not become a second what-if framework. Where a scan identifies a real exposure or exploitable weakness, the evidence-conditioned baseline is recorded first. Control what-if analysis then asks what happens if the relevant control is improved from that evidenced current state.
A9: ='OT CALC - Control What-If'!A16 | B9: ='OT CALC - Control What-If'!B16 | C9: ='OT CALC - Control What-If'!C16 | D9: ='OT CALC - Control What-If'!D16 | E9: ='OT CALC - Control What-If'!E16 | F9: =IF($B$4="Best Estimate",'OT CALC - Control What-If'!H16,'OT CALC - Control What-If'!L16) | G9: =IF($B$4="Best Estimate",'OT CALC - Control What-If'!I16,'OT CALC - Control What-If'!M16)
A10: ='OT CALC - Control What-If'!A17 | B10: ='OT CALC - Control What-If'!B17 | C10: ='OT CALC - Control What-If'!C17 | D10: ='OT CALC - Control What-If'!D17 | E10: ='OT CALC - Control What-If'!E17 | F10: =IF($B$4="Best Estimate",'OT CALC - Control What-If'!H17,'OT CALC - Control What-If'!L17) | G10: =IF($B$4="Best Estimate",'OT CALC - Control What-If'!I17,'OT CALC - Control What-If'!M17)
A11: ='OT CALC - Control What-If'!A18 | B11: ='OT CALC - Control What-If'!B18 | C11: ='OT CALC - Control What-If'!C18 | D11: ='OT CALC - Control What-If'!D18 | E11: ='OT CALC - Control What-If'!E18 | F11: =IF($B$4="Best Estimate",'OT CALC - Control What-If'!H18,'OT CALC - Control What-If'!L18) | G11: =IF($B$4="Best Estimate",'OT CALC - Control What-If'!I18,'OT CALC - Control What-If'!M18)
A12: ='OT CALC - Control What-If'!A19 | B12: ='OT CALC - Control What-If'!B19 | C12: ='OT CALC - Control What-If'!C19 | D12: ='OT CALC - Control What-If'!D19 | E12: ='OT CALC - Control What-If'!E19 | F12: =IF($B$4="Best Estimate",'OT CALC - Control What-If'!H19,'OT CALC - Control What-If'!L19) | G12: =IF($B$4="Best Estimate",'OT CALC - Control What-If'!I19,'OT CALC - Control What-If'!M19)
A13: ='OT CALC - Control What-If'!A20 | B13: ='OT CALC - Control What-If'!B20 | C13: ='OT CALC - Control What-If'!C20 | D13: ='OT CALC - Control What-If'!D20 | E13: ='OT CALC - Control What-If'!E20 | F13: =IF($B$4="Best Estimate",'OT CALC - Control What-If'!H20,'OT CALC - Control What-If'!L20) | G13: =IF($B$4="Best Estimate",'OT CALC - Control What-If'!I20,'OT CALC - Control What-If'!M20)
A14: ='OT CALC - Control What-If'!A21 | B14: ='OT CALC - Control What-If'!B21 | C14: ='OT CALC - Control What-If'!C21 | D14: ='OT CALC - Control What-If'!D21 | E14: ='OT CALC - Control What-If'!E21 | F14: =IF($B$4="Best Estimate",'OT CALC - Control What-If'!H21,'OT CALC - Control What-If'!L21) | G14: =IF($B$4="Best Estimate",'OT CALC - Control What-If'!I21,'OT CALC - Control What-If'!M21)
A15: ='OT CALC - Control What-If'!A22 | B15: ='OT CALC - Control What-If'!B22 | C15: ='OT CALC - Control What-If'!C22 | D15: ='OT CALC - Control What-If'!D22 | E15: ='OT CALC - Control What-If'!E22 | F15: =IF($B$4="Best Estimate",'OT CALC - Control What-If'!H22,'OT CALC - Control What-If'!L22) | G15: =IF($B$4="Best Estimate",'OT CALC - Control What-If'!I22,'OT CALC - Control What-If'!M22)
A16: ='OT CALC - Control What-If'!A23 | B16: ='OT CALC - Control What-If'!B23 | C16: ='OT CALC - Control What-If'!C23 | D16: ='OT CALC - Control What-If'!D23 | E16: ='OT CALC - Control What-If'!E23 | F16: =IF($B$4="Best Estimate",'OT CALC - Control What-If'!H23,'OT CALC - Control What-If'!L23) | G16: =IF($B$4="Best Estimate",'OT CALC - Control What-If'!I23,'OT CALC - Control What-If'!M23)
A17: ='OT CALC - Control What-If'!A24 | B17: ='OT CALC - Control What-If'!B24 | C17: ='OT CALC - Control What-If'!C24 | D17: ='OT CALC - Control What-If'!D24 | E17: ='OT CALC - Control What-If'!E24 | F17: =IF($B$4="Best Estimate",'OT CALC - Control What-If'!H24,'OT CALC - Control What-If'!L24) | G17: =IF($B$4="Best Estimate",'OT CALC - Control What-If'!I24,'OT CALC - Control What-If'!M24)
A18: ='OT CALC - Control What-If'!A25 | B18: ='OT CALC - Control What-If'!B25 | C18: ='OT CALC - Control What-If'!C25 | D18: ='OT CALC - Control What-If'!D25 | E18: ='OT CALC - Control What-If'!E25 | F18: =IF($B$4="Best Estimate",'OT CALC - Control What-If'!H25,'OT CALC - Control What-If'!L25) | G18: =IF($B$4="Best Estimate",'OT CALC - Control What-If'!I25,'OT CALC - Control What-If'!M25)
A19: ='OT CALC - Control What-If'!A26 | B19: ='OT CALC - Control What-If'!B26 | C19: ='OT CALC - Control What-If'!C26 | D19: ='OT CALC - Control What-If'!D26 | E19: ='OT CALC - Control What-If'!E26 | F19: =IF($B$4="Best Estimate",'OT CALC - Control What-If'!H26,'OT CALC - Control What-If'!L26) | G19: =IF($B$4="Best Estimate",'OT CALC - Control What-If'!I26,'OT CALC - Control What-If'!M26)
A20: ='OT CALC - Control What-If'!A27 | B20: ='OT CALC - Control What-If'!B27 | C20: ='OT CALC - Control What-If'!C27 | D20: ='OT CALC - Control What-If'!D27 | E20: ='OT CALC - Control What-If'!E27 | F20: =IF($B$4="Best Estimate",'OT CALC - Control What-If'!H27,'OT CALC - Control What-If'!L27) | G20: =IF($B$4="Best Estimate",'OT CALC - Control What-If'!I27,'OT CALC - Control What-If'!M27)
... A23: ='OT CALC - Control What-If'!A30 | B23: ='OT CALC - Control What-If'!B30 | C23: ='OT CALC - Control What-If'!C30 | D23: ='OT CALC - Control What-If'!D30 | E23: ='OT CALC - Control What-If'!E30 | F23: =IF($B$4="Best Estimate",'OT CALC - Control What-If'!H30,'OT CALC - Control What-If'!L30) | G23: =IF($B$4="Best Estimate",'OT CALC - Control What-If'!I30,'OT CALC - Control What-If'!M30)

Sheet 00 Risk Transfer
A1: IT / OT CYBER RISK QUANTIFICATION | RISK TRANSFER
A2: Indicative financing diagnostics using modelled annual tail risk. This is not a policy-pricing engine and does not simulate coverage terms or recoveries.
A4: Basis | B4: =IF('00 COMMON - Run Setup'!C6="IT",'IT 08 - Reporting Settings'!B16,'00 COMMON - Run Setup'!C9) | C4: Illustrative retention | D4: =IF('00 COMMON - Run Setup'!C6="IT",'IT 08 - Reporting Settings'!B18,0) | E4: Selected tail basis | F4: =IF('00 COMMON - Run Setup'!C6="IT",'IT 08 - Reporting Settings'!B17,"TVaR 99%")
A8: TAIL RISK DIAGNOSTIC
A9: Metric | B9: Value | C9: Interpretation
A10: =F4 | B10: =IF(F4="TVaR 95%",IF($B$4="Best Estimate",'00 COMMON - Output Bridge'!B17,'00 COMMON - Output Bridge'!C17),IF($B$4="Best Estimate",'00 COMMON - Output Bridge'!B19,'00 COMMON - Output Bridge'!C19)) | C10: Mean of the worst 1% of annual aggregate-loss outcomes.
A11: Tail above illustrative retention | B11: =MAX(B10-$D$4,0) | C11: TVaR99 minus retention, floored at zero. Indicative only.
A12: P(any successful event) | B12: =IF($B$4="Best Estimate",'00 COMMON - Output Bridge'!B20,'00 COMMON - Output Bridge'!C20) | C12: Positive-loss year share from the selected model view.
A15: RETURN-PERIOD LOSS DIAGNOSTIC
A16: Return period | B16: Exceedance probability | C16: AEP loss | D16: Loss above retention
A17: 2 | B17: ='00 COMMON - Output Bridge'!A43 | C17: =IF($B$4="Best Estimate",'00 COMMON - Output Bridge'!B43,'00 COMMON - Output Bridge'!D43) | D17: =MAX(C17-$D$4,0)
A18: 5 | B18: ='00 COMMON - Output Bridge'!A44 | C18: =IF($B$4="Best Estimate",'00 COMMON - Output Bridge'!B44,'00 COMMON - Output Bridge'!D44) | D18: =MAX(C18-$D$4,0)
A19: 10 | B19: ='00 COMMON - Output Bridge'!A45 | C19: =IF($B$4="Best Estimate",'00 COMMON - Output Bridge'!B45,'00 COMMON - Output Bridge'!D45) | D19: =MAX(C19-$D$4,0)
A20: 20 | B20: ='00 COMMON - Output Bridge'!A46 | C20: =IF($B$4="Best Estimate",'00 COMMON - Output Bridge'!B46,'00 COMMON - Output Bridge'!D46) | D20: =MAX(C20-$D$4,0)
A21: 25 | B21: ='00 COMMON - Output Bridge'!A47 | C21: =IF($B$4="Best Estimate",'00 COMMON - Output Bridge'!B47,'00 COMMON - Output Bridge'!D47) | D21: =MAX(C21-$D$4,0)
A22: 50 | B22: ='00 COMMON - Output Bridge'!A48 | C22: =IF($B$4="Best Estimate",'00 COMMON - Output Bridge'!B48,'00 COMMON - Output Bridge'!D48) | D22: =MAX(C22-$D$4,0)
A23: 100 | B23: ='00 COMMON - Output Bridge'!A49 | C23: =IF($B$4="Best Estimate",'00 COMMON - Output Bridge'!B49,'00 COMMON - Output Bridge'!D49) | D23: =MAX(C23-$D$4,0)
A24: 200 | B24: ='00 COMMON - Output Bridge'!A50 | C24: =IF($B$4="Best Estimate",'00 COMMON - Output Bridge'!B50,'00 COMMON - Output Bridge'!D50) | D24: =MAX(C24-$D$4,0)
A25: 250 | B25: ='00 COMMON - Output Bridge'!A51 | C25: =IF($B$4="Best Estimate",'00 COMMON - Output Bridge'!B51,'00 COMMON - Output Bridge'!D51) | D25: =MAX(C25-$D$4,0)
A26: 500 | B26: ='00 COMMON - Output Bridge'!A52 | C26: =IF($B$4="Best Estimate",'00 COMMON - Output Bridge'!B52,'00 COMMON - Output Bridge'!D52) | D26: =MAX(C26-$D$4,0)

Sheet 2 User-input navigation
A1: 2 User-input navigation
A2: Editable assessment inputs. Complete only the selected IT or OT domain; outside-in evidence remains optional.
A3: =IF('00 COMMON - Run Setup'!C6="IT","Complete the IT input section only",IF('00 COMMON - Run Setup'!C6="OT","Complete the OT input section only","Set Model domain first"))
A4: Common every run: 00 COMMON - Run Setup; 00 COMMON - Outside-In (optional).
A5: IT only: IT 03, optional IT 04, IT 05, IT 06 overrides, IT 07 adjustments, IT 08 reporting.
A6: OT only: OT 03, OT 04, OT 05, OT 06 adjustments.
A7: Governed packs and core methodology are Advanced / Read Only / Not required to complete an assessment.
A8: 04 Control Assessment | B8: Assessment input / configuration | C8: =HYPERLINK("#'OT 04 - Control Assessment'!A1","Open")
A9: 05 Impact and BIA | B9: Assessment input / configuration | C9: =HYPERLINK("#'OT 05 - Impact & BIA'!A1","Open")
A10: IT 03 Organisation Inputs | B10: Assessment input / configuration | C10: =HYPERLINK("#'IT 03 - Organisation Inputs'!A1","Open")
A11: IT 05 Control Assessment | B11: Assessment input / configuration | C11: =HYPERLINK("#'IT 05 - Control Assessment'!A1","Open")
A12: IT 06 Impact and BIA | B12: Assessment input / configuration | C12: =HYPERLINK("#'IT 06 - Impact & BIA Overrides'!A1","Open")

Sheet 00 COMMON - Run Setup
A1: GUIDED IT / OT CYBER RISK QUANTIFICATION — RUN SETUP
A2: Single assessment front end. Sector selection routes to the governed IT or OT methodology; outside-in evidence is optional and must never be treated as a standalone risk score.
A4: ASSESSMENT & MODEL ROUTING
A5: Input | B5: Purpose | C5: Selection | Z5: IT | AA5: Financial Services | AB5: Power Generation
A6: Model domain | B6: Explicit user selection. Filters the Sector list. | C6: OT | Z6: OT | AA6: Financial_Services | AB6: Energy Assets
A7: Sector | B7: Filtered by Model domain. Resolves the external sector pack. | C7: Power Generation | AB7: Manufacturing
A8: Asset type / scope | B8: Filtered by Sector: Organisation for IT; facility archetype for OT. | C8: CCGT | D8: =IF(C6="IT",IF(C8="Organisation","","IT requires Asset type = Organisation"),"") | Z8: Organisation
A9: Basis | B9: Best Estimate or Prudent dashboard view. | C9: Prudent
A10: Apply outside-in scan? | B10: Optional evidence layer. No scan = baseline model remains fully valid. | C10: No
A11: Outside-in file | B11: Expected relative path for approved normalized scan results. | C11: ="evidence/outside_in/"&IF(C6="OT",'OT 03 - Facility Inputs'!C16,'IT 03 - Organisation Inputs'!C16)&"_outside_in.csv"
A12: Resolved engine | B12: Common runner dispatches to the governed domain engine. | C12: =IF(C6="IT","it_crq v1.1.1","ot_crq v1.7.1")
A13: Unit of analysis | B13: Organisation for IT; one facility for OT. | C13: =IF(C6="IT","Organisation","Facility")
A14: Resolved pack | B14: Engine-resolved pack identifier. | C14: =IF(C6="OT",'OT 03 - Facility Inputs'!C32,'IT 03 - Organisation Inputs'!C34)
A17: DOMAIN ROUTING CONTRACT
A18: Sector | B18: Domain | C18: Unit | D18: Underlying methodology | E18: Engine | F18: Template / pack | G18: Outside-in allowed? | H18: Routing note
A19: Financial Services | B19: IT | C19: Organisation | D19: IT-CRQ v1.1.1 | E19: it_crq | F19: Guided_IT_CRQ_Model_v1_1_1_Dashboard.xlsx / FS-v1.1.1 | G19: Yes | H19: Enterprise ATT&CK; 4 actors; IT scenario/route model.
A20: Power Generation | B20: OT | C20: Facility | D20: OT-CRQ v1.7 + PG pack | E20: ot_crq | F20: PG-v1.6 | G20: Yes | H20: ATT&CK for ICS; 3 actors; five-stage OT composite path.
A21: Energy Assets | B21: OT | C21: Facility | D21: OT-CRQ v1.7 + EA pack | E21: ot_crq | F21: EA-v1.0 | G21: Yes | H21: Same OT method; Energy calibration pack.
A22: Manufacturing | B22: OT | C22: Facility | D22: OT-CRQ v1.7 + MF pack | E22: ot_crq | F22: MF-v1.0 | G22: Yes | H22: Same OT method; Manufacturing calibration pack.
A25: RUN WORKFLOW
A26: Step | B26: Operator action | C26: Engine behaviour | D26: Audit result
A27: 1 | B27: Select sector and scope above. | C27: Router resolves IT vs OT and governed pack. | D27: Domain/pack recorded in result workbook.
A28: 2 | B28: Complete the relevant IT or OT assessment inputs. | C28: Only the selected domain methodology is executed. | D28: Unselected domain is not blended into the result.
A29: 3 | B29: If a scan exists, set Apply outside-in = Yes and place normalized file at the shown path. | C29: Engine validates schema, attribution and approved mapping rules. | D29: 00 Outside-In stores the normalized evidence snapshot.
A30: 4 | B30: Run the common launcher. | C30: Launcher dispatches to it_crq or ot_crq. | D30: Baseline assumptions and scan-conditioned amendments are preserved separately.
A31: 5 | B31: Review dashboards and validation. | C31: Dashboard reads the common output bridge. | D31: 00 OI Adjustment Rationale explains every quantitative amendment.
A32: 6 | B32: Archive workbook + scan + engine version. | C32: No scan is a valid run state. | D32: Reproducible assessment package.
A35: EXECUTION CONTRACT — one combined workbook is the operator-facing assessment file. The common Python launcher routes by sector. IT runs use the supplied v1.1.1 code against the IT staging sheets; OT runs remain on the governed OT methodology. The unselected domain is not blended into the calculation.
A42: FINANCIAL SERVICES — IT INPUT SYNC CONTRACT
A43: Combined workbook sheet | B43: IT template destination | C43: Values to sync | D43: Direction | E43: When | F43: Purpose
A44: IT 03 Organisation Inputs | B44: 03 Organisation Inputs | C44: User input cells / keys | D44: Master → IT template | E44: Before IT run | F44: Organisation scale and model settings
A45: IT 05 Control Assessment | B45: 05 Control Assessment | C45: Actual maturity / coverage / evidence | D45: Master → IT template | E45: Before IT run | F45: Control barriers
A46: IT 06 Impact and BIA | B46: 06 Impact and BIA | C46: Organisation overrides | D46: Master → IT template | E46: Before IT run | F46: Financial consequence
A47: IT 07 Frequency Assumptions | B47: 07 Frequency Assumptions | C47: User input frequency multipliers | D47: Master → IT template | E47: Before IT run | F47: Campaign frequency
A48: IT 08 Tail Risk Settings | B48: 08 Tail Risk Settings | C48: Reporting / retention inputs | D48: Master → IT template | E48: Before IT run | F48: Reporting configuration
A49: 00 Output Bridge | B49: IT result workbook | C49: Normalized metrics / curves / decompositions | D49: IT result → Master | E49: After IT run | F49: Common dashboards
A50: Required workflow
A51: =IF(C6="IT","Complete the IT input section only",IF(C6="OT","Complete the OT input section only","Select IT or OT"))
A52: Parameter | B52: Description | C52: Value
A53: Selected domain | B53: =C6
...

Sheet 00 COMMON - Outside-In
A1: OPTIONAL OUTSIDE-IN EVIDENCE
A2: Engine-populated normalized scan evidence. The model must run with this sheet empty when no scan is available. Positive evidence may condition existing likelihood inputs; absence of a finding does not automatically earn risk credit.
A4: SCAN STATUS & GOVERNANCE
A5: Field | B5: Value | D5: INCLUSION RULES • Finding must map to an in-scope organisation/facility asset or route. • Direct exposure can change exposure/frequency or route feasibility. • KEV/high-EPSS/CVE evidence can inform the relevant access/stage barrier; EPSS is not P(success). • Do not change financial severity, downtime, physical damage or safety consequence solely from outside-in data. • Uncertain ownership or facility attribution is retained as evidence but receives no automatic quantitative adjustment. • A clean scan does not, by itself, reduce baseline risk.
A6: Apply outside-in? | B6: ='00 COMMON - Run Setup'!C10
A7: Expected file | B7: ='00 COMMON - Run Setup'!C11
A8: Scan supplied? | B8: No
A9: Schema status | B9: NOT LOADED
A10: Finding count | B10: 0
A11: Quantitative adjustments | B11: 0
A12: Scan / observation date
A14: NORMALIZED FINDING SNAPSHOT — ENGINE OUTPUT
A15: Finding ID | B15: Observed asset / endpoint | C15: Finding type | D15: Technology / service | E15: CVE | F15: KEV? | G15: EPSS | H15: Internet exposed? | I15: Organisation attribution | J15: Facility attribution | K15: Attribution confidence | L15: IT/OT relevance | M15: ATT&CK / route mapping | N15: Model stage | O15: Proposed treatment | P15: Evidence strength | Q15: Source / scanner | R15: Observation date

Sheet 3 Assumption Ownership
A1: 3 Assumption Ownership
A2: Governed calibration, scenario/TTP mappings, sector packs and frequency/tail assumptions.
A3: Group | B3: Domain | C3: Sector | D3: Assumption layer | E3: Sheet or file | F3: Purpose | G3: Owner | H3: Editable during assessment? | I3: Authoritative location | J3: Required evidence | K3: Calibration status
A4: 1 Common setup | B4: Common | C4: All | D4: Assessment setup | E4: 00 COMMON - Run Setup | F4: Domain, sector, pack, basis, outside-in | G4: Assessment Team | H4: Yes | I4: 00 COMMON - Run Setup | J4: Assessment ID / sector selection | K4: n/a
A5: 1 Common setup | B5: Common | C5: All | D5: Optional evidence | E5: 00 COMMON - Outside-In | F5: Approved outside-in findings | G5: Assessment Team | H5: Optional | I5: 00 COMMON - Outside-In | J5: Approved CSV | K5: n/a
A6: 2 IT assessment | B6: IT | C6: Financial Services | D6: Assessment input | E6: IT 03 - Organisation Inputs | F6: Organisation scale and run inputs | G6: Assessment Team | H6: Yes | I6: IT 03 - Organisation Inputs | J6: Client evidence | K6: n/a
A7: 2 IT assessment | B7: IT | C7: Financial Services | D7: Optional override | E7: IT 04 - Exposure Adjustments | F7: Exposure-model recommendations | G7: Assessment Team | H7: Optional | I7: IT 04 - Exposure Adjustments | J7: Exposure model | K7: n/a
A8: 2 IT assessment | B8: IT | C8: Financial Services | D8: Assessment input | E8: IT 05 - Control Assessment | F8: Actual IT control maturity | G8: Assessment Team | H8: Yes | I8: IT 05 - Control Assessment | J8: Control evidence | K8: n/a
A9: 2 IT assessment | B9: IT | C9: Financial Services | D9: Optional override | E9: IT 06 - Impact & BIA Overrides | F9: Org-specific BIA overrides | G9: Assessment Team | H9: Optional | I9: IT 06; blank keeps pack | J9: Org BIA | K9: n/a
A10: 2 IT assessment | B10: IT | C10: Financial Services | D10: Optional override | E10: IT 07 - Assessment Adjustments | F10: Org frequency/threat overlays | G10: Assessment Team | H10: Optional | I10: IT 07; pack owns reference λ | J10: Threat intel | K10: n/a
A11: 2 IT assessment | B11: IT | C11: Financial Services | D11: Assessment input | E11: IT 08 - Reporting Settings | F11: Basis, retention, tail metric | G11: Assessment Team | H11: Yes | I11: IT 08 - Reporting Settings | J11: Reporting policy | K11: n/a
A12: 3 Core IT | B12: IT | C12: All IT | D12: Core methodology | E12: IT CORE / IT CALC sheets | F12: IT calculation method | G12: Core IT Model Owner | H12: No | I12: src/it_crq + IT CORE sheets | J12: n/a | K12: Governed
A13: 4 FS pack | B13: IT | C13: Financial Services | D13: Sector pack | E13: sector_packs/IT/IT_CRQ_Sector_Pack_Financial_Services_v1_1_1.xlsx | F13: FS reference calibration | G13: Sector Pack Owner | H13: No | I13: External FS pack | J13: Pack evidence register | K13: Working priors
A14: 5 OT assessment | B14: OT | C14: Selected OT sector | D14: Assessment input | E14: OT 03 - Facility Inputs | F14: Facility identity and architecture | G14: Assessment Team | H14: Yes | I14: OT 03 - Facility Inputs | J14: Facility evidence | K14: n/a
... A22: 10 Outputs | B22: Common | C22: All | D22: Calculated | E22: 00 dashboards / Engine Results | F22: AAL, LEC, validation | G22: Python engine | H22: No | I22: 00 COMMON - Engine Results | J22: n/a | K22: Run-specific

Sheet FILL IT assessment only
A1: FILL IT assessment only
A3: =IF('00 COMMON - Run Setup'!C6="IT","FILL the cyan IT tabs. Ignore FILL OT.","Not used for this run.")

Sheet IT 03 - Organisation Inputs
A1: 03 — Organisation and Run Inputs
A2: Select the sector, organisation scale and whether upstream IT Exposure Adjustment Model recommendations are applied.
A3: =IF('00 COMMON - Run Setup'!C6="IT","FILL this sheet — IT assessment.","Not used for this run. Complete the OT assessment section only.")
A4: Enter organisation identity and scale here. Python uses these Value cells for the IT calculation. Sector is taken from Run Setup. Currency and Use exposure model are dropdowns.
A15: Input | B15: Question | C15: Value | D15: Type | E15: How used | F15: Basis / evidence
A16: ASSESSMENT_ID | B16: Assessment reference | C16: IT-CRQ-001 | D16: Text | E16: Reporting and traceability | F16: Client
A17: ORGANISATION | B17: Organisation | C17: Example Financial Institution | D17: Text | E17: Organisation-level unit of analysis | F17: Client
A18: COUNTRY_REGION | B18: Country / region | C18: UAE / GCC | D18: Text | E18: Reporting context; explicit multiplier is on 07 | F18: Client
A19: SECTOR | B19: Sector | C19: ='00 COMMON - Run Setup'!C7 | D19: Dropdown | E19: Resolves the separate sector-pack workbook | F19: 09 Sector Pack Registry
A20: CURRENCY | B20: Reporting currency | C20: USD | D20: Dropdown | E20: Financial result labels | F20: Client
A21: ANNUAL_REVENUE_AT_RISK | B21: Annual revenue at risk | C21: 1000000000 | D21: Currency/year | E21: Business interruption and revenue-scaled drivers | F21: Client Finance
A22: ANNUAL_PAYMENT_VALUE | B22: Annual payment / transaction value | C22: 5000000000 | D22: Currency/year | E22: Funds-at-risk model for integrity and fraud scenarios | F22: Client Finance
A23: BI_LOSS_FACTOR | B23: Business-interruption loss factor | C23: 1 | D23: Percentage | E23: Share of revenue at risk treated as avoidable loss | F23: Client Finance
A24: EMPLOYEES | B24: Employees | C24: 10000 | D24: Count | E24: Organisation context | F24: Client
A25: CUSTOMERS | B25: Customers / accounts | C25: 2000000 | D25: Count | E25: Potential notification and monitoring scale | F25: Client
A26: SENSITIVE_RECORDS | B26: Sensitive records | C26: 5000000 | D26: Count | E26: Data-compromise scaling | F26: Client
A27: CRITICAL_ENDPOINTS | B27: Critical endpoints | C27: 5000 | D27: Count | E27: Recovery-cost scaling | F27: Client
A28: CRITICAL_SERVERS | B28: Critical servers / workloads | C28: 500 | D28: Count | E28: Recovery-cost scaling | F28: Client
A29: USE_EXPOSURE_MODEL | B29: Use IT Exposure Adjustment Model inputs? | C29: No | D29: Yes / No dropdown | E29: Controls whether sheet 04 recommendations are applied | F29: User decision
A30: SIMULATION_YEARS | B30: Monte Carlo organisation-years | C30: 500000 | D30: Count | E30: Annual-loss simulation size | F30: Model setting
A31: RANDOM_SEED | B31: Random seed | C31: 20260821 | D31: Integer | E31: Reproducible simulation | F31: Model setting
A33: RESOLVED SECTOR PACK
A34: PACK_ID | B34: Resolved pack ID | C34: FS-v1.1.1 | D34: Engine output | E34: Traceability | F34: Separate sector-pack workbook
A35: PACK_VERSION | B35: Resolved pack version | C35: 1.1.1 | D35: Engine output | E35: Compatibility | F35: Separate sector-pack workbook
A36: PACK_STATUS | B36: Pack calibration status | C36: Development — working priors; calibration required | D36: Engine output | E36: Governance | F36: Separate sector-pack workbook
A37: MODEL_STATUS | B37: Last validation status | C37: PASS | D37: Engine output | E37: Model governance | F37: 22 Validation Tests
A40: COMBINED-MODEL NOTE — These IT sheets are the user-input staging area for Financial Services. The common runner must copy the staged values into the governed IT v1.1.1 template, execute it_crq, then write the normalized results back to 00 Output Bridge. The IT calculation methodology itself is not replaced by OT logic.

Sheet IT 04 - Exposure Adjustments
A1: 04 — IT Exposure Adjustment Inputs
A2: Optional upstream recommendations. The CRQ workbook does not ingest raw asset or vulnerability records.
A3: =IF('00 COMMON - Run Setup'!C6="IT","FILL this sheet — IT assessment.","Not used for this run. Complete the OT assessment section only.")
A4: Optional. Leave this sheet at Yes / Unknown / 1.0 unless you set USE_EXPOSURE_MODEL = Yes on IT 03 and have a governed exposure-model recommendation. Organisation applicable? can still mark a route as out of scope.
A15: Route ID | B15: Attack route | C15: Organisation applicable? | D15: Evidence-model feasible? | E15: Opportunity factor | F15: S1 factor | G15: S2 factor | H15: S3 factor | I15: S4 factor | J15: S5 factor | K15: Impact factor | L15: Confidence | M15: Recommendation ID | N15: Evidence date | O15: Rationale | P15: Used opportunity | Q15: Used S1 | R15: Used S2 | S15: Used S3 | T15: Used S4 | U15: Used S5 | V15: Used impact
A16: R_ID | B16: Identity and credential compromise | C16: Yes | D16: Unknown | E16: 1 | F16: 1 | G16: 1 | H16: 1 | I16: 1 | J16: 1 | K16: 1 | L16: Not assessed | O16: No exposure-model recommendation loaded. | P16: 1 | Q16: 1 | R16: 1 | S16: 1 | T16: 1 | U16: 1 | V16: 1
A17: R_USER | B17: User endpoint and social engineering | C17: Yes | D17: Unknown | E17: 1 | F17: 1 | G17: 1 | H17: 1 | I17: 1 | J17: 1 | K17: 1 | L17: Not assessed | O17: No exposure-model recommendation loaded. | P17: 1 | Q17: 1 | R17: 1 | S17: 1 | T17: 1 | U17: 1 | V17: 1
A18: R_EXP | B18: Public-facing application exploitation | C18: Yes | D18: Unknown | E18: 1 | F18: 1 | G18: 1 | H18: 1 | I18: 1 | J18: 1 | K18: 1 | L18: Not assessed | O18: No exposure-model recommendation loaded. | P18: 1 | Q18: 1 | R18: 1 | S18: 1 | T18: 1 | U18: 1 | V18: 1
A19: R_TP | B19: Third-party or software supply chain | C19: Yes | D19: Unknown | E19: 1 | F19: 1 | G19: 1 | H19: 1 | I19: 1 | J19: 1 | K19: 1 | L19: Not assessed | O19: No exposure-model recommendation loaded. | P19: 1 | Q19: 1 | R19: 1 | S19: 1 | T19: 1 | U19: 1 | V19: 1
A20: R_DDOS | B20: Direct availability or DDoS | C20: Yes | D20: Unknown | E20: 1 | F20: 1 | G20: 1 | H20: 1 | I20: 1 | J20: 1 | K20: 1 | L20: Not assessed | O20: No exposure-model recommendation loaded. | P20: 1 | Q20: 1 | R20: 1 | S20: 1 | T20: 1 | U20: 1 | V20: 1
A21: R_INS | B21: Insider or trusted access | C21: Yes | D21: Unknown | E21: 1 | F21: 1 | G21: 1 | H21: 1 | I21: 1 | J21: 1 | K21: 1 | L21: Not assessed | O21: No exposure-model recommendation loaded. | P21: 1 | Q21: 1 | R21: 1 | S21: 1 | T21: 1 | U21: 1 | V21: 1

Sheet IT 05 - Control Assessment
A1: 05 — Control Assessment
A2: NIST CSF 2.0-aligned control families with Enterprise ATT&CK mitigation mappings and reference-relative efficacy.
A3: =IF('00 COMMON - Run Setup'!C6="IT","FILL this sheet — IT assessment.","Not used for this run. Complete the OT assessment section only.")
A15: Control ID | B15: Control family | C15: NIST CSF 2.0 | D15: MITRE mitigations | E15: Actual maturity | F15: Actual coverage | G15: Reference maturity | H15: Reference coverage | I15: Evidence / rationale | J15: Resolved status
A16: C01 | B16: Asset and vulnerability management | C16: ID.AM; ID.RA | D16: M1016; M1051 | E16: Developing | F16: 0.75 | G16: Developing | H16: 0.75 | I16: User assessment required | J16: Working prior
A17: C02 | B17: Identity, authentication and MFA | C17: PR.AA | D17: M1032; M1036 | E17: Developing | F17: 0.75 | G17: Developing | H17: 0.75 | I17: User assessment required | J17: Working prior
A18: C03 | B18: Privileged access management | C18: PR.AA | D18: M1026; M1018 | E18: Developing | F18: 0.75 | G18: Developing | H18: 0.75 | I18: User assessment required | J18: Working prior
A19: C04 | B19: Email, web security and awareness | C19: PR.AT; PR.DS | D19: M1017; M1021 | E19: Developing | F19: 0.75 | G19: Developing | H19: 0.75 | I19: User assessment required | J19: Working prior
A20: C05 | B20: Endpoint protection and execution control | C20: PR.PS; DE.CM | D20: M1040; M1049 | E20: Developing | F20: 0.75 | G20: Developing | H20: 0.75 | I20: User assessment required | J20: Working prior
A21: C06 | B21: Secure configuration and patching | C21: PR.PS | D21: M1042; M1051 | E21: Developing | F21: 0.75 | G21: Developing | H21: 0.75 | I21: User assessment required | J21: Working prior
A22: C07 | B22: Network security and segmentation | C22: PR.IR; PR.PS | D22: M1030; M1037 | E22: Developing | F22: 0.75 | G22: Developing | H22: 0.75 | I22: User assessment required | J22: Working prior
A23: C08 | B23: Cloud and SaaS security | C23: PR.AA; PR.PS; DE.CM | D23: M1047; M1032 | E23: Developing | F23: 0.75 | G23: Developing | H23: 0.75 | I23: User assessment required | J23: Working prior
A24: C09 | B24: Application and API security | C24: ID.RA; PR.PS | D24: M1050; M1051 | E24: Developing | F24: 0.75 | G24: Developing | H24: 0.75 | I24: User assessment required | J24: Working prior
A25: C10 | B25: Logging, detection and threat response | C25: DE.CM; DE.AE; RS.AN | D25: M1047 | E25: Developing | F25: 0.75 | G25: Developing | H25: 0.75 | I25: User assessment required | J25: Working prior
A26: C11 | B26: Data protection and DLP | C26: PR.DS | D26: M1041; M1057 | E26: Developing | F26: 0.75 | G26: Developing | H26: 0.75 | I26: User assessment required | J26: Working prior
A27: C12 | B27: Third-party and supply-chain security | C27: GV.SC; ID.RA | D27: M1045; M1051 | E27: Developing | F27: 0.75 | G27: Developing | H27: 0.75 | I27: User assessment required | J27: Working prior
... A30: C15 | B30: Payment and fraud controls | C30: PR.AA; DE.AE; RS.MI | D30: M1018; M1047 | E30: Developing | F30: 0.75 | G30: Developing | H30: 0.75 | I30: User assessment required | J30: Working prior

Sheet IT 06 - Impact & BIA Overrides
A1: 06 — Impact and Business Impact Analysis
A2: Pack-driven P50/P99 assumptions. Python prepares this long table and preserves overrides.
A3: =IF('00 COMMON - Run Setup'!C6="IT","FILL this sheet — IT assessment.","Not used for this run. Complete the OT assessment section only.")
A4: Organisation-scale figures below are live links to IT 03 — do not type them here. On this sheet, fill Override P50/P99 only where you have organisation-specific BIA evidence. Leave overrides blank to keep the Financial Services pack baseline.
A5: ORGANISATION-SCALE INPUTS
A6: Metric | B6: Value | C6: Source
A7: Annual revenue at risk | B7: ='IT 03 - Organisation Inputs'!C21 | C7: IT 03 - Organisation Inputs (live)
A8: Annual payment value | B8: ='IT 03 - Organisation Inputs'!C22 | C8: IT 03 - Organisation Inputs (live)
A9: BI loss factor | B9: ='IT 03 - Organisation Inputs'!C23 | C9: IT 03 - Organisation Inputs (live)
A10: Customers | B10: ='IT 03 - Organisation Inputs'!C25 | C10: IT 03 - Organisation Inputs (live)
A11: Sensitive records | B11: ='IT 03 - Organisation Inputs'!C26 | C11: IT 03 - Organisation Inputs (live)
A12: Critical endpoints | B12: ='IT 03 - Organisation Inputs'!C27 | C12: IT 03 - Organisation Inputs (live)
A13: Critical servers | B13: ='IT 03 - Organisation Inputs'!C28 | C13: IT 03 - Organisation Inputs (live)
A15: PACK ASSUMPTIONS AND ORGANISATION OVERRIDES
A16: Assumption type | B16: Scenario ID | C16: Scenario | D16: Parameter ID | E16: Description | F16: Unit | G16: Pack P50 | H16: Pack P99 | I16: Override P50 | J16: Override P99 | K16: Used P50 | L16: Used P99 | M16: Evidence grade | N16: Source ID
A17: RATE | D17: NOTIFICATION_PER_RECORD | E17: Notification cost per affected record | F17: USD/record | G17: 0.5 | H17: 1 | K17: 0.5 | L17: 1 | M17: D | N17: SRC-07
A18: RATE | D18: CREDIT_MONITORING_PER_RECORD | E18: Credit monitoring per participating record | F18: USD/record | G18: 8 | H18: 20 | K18: 8 | L18: 20 | M18: D | N18: SRC-07
A19: RATE | D19: FORENSIC_DAILY | E19: Daily forensic investigation team | F19: USD/day | G19: 2000 | H19: 4000 | K19: 2000 | L19: 4000 | M19: D | N19: SRC-07
A20: RATE | D20: EXTERNAL_CYBER_DAILY | E20: Daily external cyber response team | F20: USD/day | G20: 3000 | H20: 5000 | K20: 3000 | L20: 5000 | M20: D | N20: SRC-07
A21: RATE | D21: RESTORATION_DAILY | E21: Daily data restoration team | F21: USD/day | G21: 2000 | H21: 4000 | K21: 2000 | L21: 4000 | M21: D | N21: SRC-07
A22: RATE | D22: LEGAL_DAILY | E22: Daily external legal team | F22: USD/day | G22: 5000 | H22: 10000 | K22: 5000 | L22: 10000 | M22: D | N22: SRC-07
A23: RATE | D23: ENDPOINT_REPAIR | E23: Endpoint repair/replacement unit cost | F23: USD/endpoint | G23: 200 | H23: 500 | K23: 200 | L23: 500 | M23: D | N23: SRC-07
A24: RATE | D24: SERVER_REPAIR | E24: Server repair/replacement unit cost | F24: USD/server | G24: 5000 | H24: 8000 | K24: 5000 | L24: 8000 | M24: D | N24: SRC-07
A25: PARAM | B25: SC_DISR | C25: Critical business-service disruption | D25: AFFECTED_ENDPOINT_SHARE | E25: AFFECTED_ENDPOINT_SHARE | F25: share | G25: 0.1 | H25: 0.5 | K25: 0.1 | L25: 0.5 | M25: D | N25: SRC-10
A26: PARAM | B26: SC_DISR | C26: Critical business-service disruption | D26: AFFECTED_RECORD_SHARE | E26: AFFECTED_RECORD_SHARE | F26: share | G26: 0 | H26: 0.05 | K26: 0 | L26: 0.05 | M26: D | N26: SRC-10
A27: PARAM | B27: SC_DISR | C27: Critical business-service disruption | D27: AFFECTED_SERVER_SHARE | E27: AFFECTED_SERVER_SHARE | F27: share | G27: 0.1 | H27: 0.6 | K27: 0.1 | L27: 0.6 | M27: D | N27: SRC-10
A28: PARAM | B28: SC_DISR | C28: Critical business-service disruption | D28: AFFECTED_SERVICE_SHARE | E28: AFFECTED_SERVICE_SHARE | F28: share | G28: 0.3 | H28: 0.85 | K28: 0.3 | L28: 0.85 | M28: D | N28: SRC-10
A29: PARAM | B29: SC_DISR | C29: Critical business-service disruption | D29: CHURN_REVENUE_SHARE | E29: CHURN_REVENUE_SHARE | F29: share | G29: 0.001 | H29: 0.01 | K29: 0.001 | L29: 0.01 | M29: D | N29: SRC-10
A30: PARAM | B30: SC_DISR | C30: Critical business-service disruption | D30: CYBER_DAYS | E30: CYBER_DAYS | F30: days | G30: 10 | H30: 90 | K30: 10 | L30: 90 | M30: D | N30: SRC-10
A31: PARAM | B31: SC_DISR | C31: Critical business-service disruption | D31: DIVERTED_SHARE | E31: DIVERTED_SHARE | F31: share | G31: 0 | H31: 0 | K31: 0 | L31: 0 | M31: D | N31: SRC-10
A32: PARAM | B32: SC_DISR | C32: Critical business-service disruption | D32: DOWNTIME_DAYS | E32: DOWNTIME_DAYS | F32: days | G32: 3 | H32: 30 | K32: 3 | L32: 30 | M32: D | N32: SRC-10
A33: PARAM | B33: SC_DISR | C33: Critical business-service disruption | D33: EXTORTION_DIRECT | E33: EXTORTION_DIRECT | F33: USD | G33: 1000000 | H33: 20000000 | K33: 1000000 | L33: 20000000 | M33: D | N33: SRC-10
A34: PARAM | B34: SC_DISR | C34: Critical business-service disruption | D34: FRAUD_RECOVERY_RATE | E34: FRAUD_RECOVERY_RATE | F34: share | G34: 0 | H34: 0 | K34: 0 | L34: 0 | M34: D | N34: SRC-10
A35: PARAM | B35: SC_DISR | C35: Critical business-service disruption | D35: IR_DAYS | E35: IR_DAYS | F35: days | G35: 10 | H35: 60 | K35: 10 | L35: 60 | M35: D | N35: SRC-10
A36: PARAM | B36: SC_DISR | C36: Critical business-service disruption | D36: LEGAL_DAYS | E36: LEGAL_DAYS | F36: days | G36: 5 | H36: 45 | K36: 5 | L36: 45 | M36: D | N36: SRC-10
... A92: PARAM | B92: SC_FRAUD | C92: Cyber-enabled theft or fraud | D92: RESTORE_DAYS | E92: RESTORE_DAYS | F92: days | G92: 5 | H92: 60 | K92: 5 | L92: 60 | M92: D | N92: SRC-10

Sheet IT 07 - Assessment Adjustments
A1: 07 — Frequency Assumptions
A2: Best-estimate campaign frequency remains separate from conditional attack-path success and prudence.
A3: =IF('00 COMMON - Run Setup'!C6="IT","FILL this sheet — IT assessment.","Not used for this run. Complete the OT assessment section only.")
A4: Organisation-level overlays only. Pack-owned campaign rate, actor weights and route priors are read-only.
A15: Parameter | B15: Value | C15: Unit | D15: How used | E15: Status | F15: Source / rationale
A16: ORGANISATION_EXPOSURE_MULT | B16: 1 | C16: multiplier | D16: Scales reference material campaign rate before actor/scenario/route allocation | E16: User input | F16: Organisation context; avoid duplicating sheet 04 route factors
A17: GEOGRAPHY_THREAT_MULT | B17: 1 | C17: multiplier | D17: Scales campaign rate for geography-specific threat context | E17: User input | F17: Use 1.00 unless evidence supports adjustment
A18: PRUDENCE_FREQUENCY_FACTOR | B18: 1.25 | C18: multiplier | D18: Applied only to prudent frequency view | E18: User input | F18: Separate named prudence margin
A19: NATION_STATE_ACTIVITY | B19: 1 | C19: multiplier | D19: Actor-specific activity adjustment | E19: User input | F19: Client threat intelligence
A20: CYBERCRIMINAL_ACTIVITY | B20: 1 | C20: multiplier | D20: Actor-specific activity adjustment | E20: User input | F20: Client threat intelligence
A21: MALICIOUS_INSIDER_ACTIVITY | B21: 1 | C21: multiplier | D21: Actor-specific activity adjustment | E21: User input | F21: Client threat intelligence
A22: HACKTIVIST_ACTIVITY | B22: 1 | C22: multiplier | D22: Actor-specific activity adjustment | E22: User input | F22: Client threat intelligence
A25: RESOLVED PACK FREQUENCY
A26: REFERENCE_CAMPAIGNS_PER_YEAR | B26: 1 | C26: campaigns/org-year | D26: Loaded from selected sector pack | E26: Engine output | F26: Development working prior
A27: PACK_WEIGHTED_ACTIVITY | B27: 1 | C27: multiplier | D27: Σ(actor weight × actor activity) | E27: Engine output | F27: Calculation
A28: BEST_ESTIMATE_LAMBDA | B28: 1 | C28: campaigns/org-year | D28: Reference × organisation × geography × weighted activity | E28: Engine output | F28: Calculation
A29: PRUDENT_LAMBDA | B29: 1.25 | C29: campaigns/org-year | D29: Best estimate × prudence factor | E29: Engine output | F29: Calculation
A30: ACTIVE_ROUTE_OPPORTUNITY | B30: 1 | C30: multiplier | D30: Resulting route-level exposure effect | E30: Engine output | F30: Calculation

Sheet IT 08 - Reporting Settings
A1: 08 — Tail-Risk and Reporting Settings
A2: User-selected tail metric and insurance retention; both best-estimate and prudent views remain available.
A3: =IF('00 COMMON - Run Setup'!C6="IT","FILL this sheet — IT assessment.","Not used for this run. Complete the OT assessment section only.")
A4: Set reporting basis (Best Estimate vs Prudent), TVaR 95 vs TVaR 99, and illustrative insurance retention here. 00 Risk Transfer, the executive dashboard Basis, and the IT engine all read these three cells.
A15: Parameter | B15: Value | C15: Type | D15: How used | E15: Status | F15: Notes
A16: REPORTING_VIEW | B16: Prudent | C16: Dropdown | D16: Detailed-sheet presentation | E16: User input | F16: Executive summary always shows both views
A17: TVAR_SELECTION | B17: TVaR 99% | C17: Dropdown | D17: Selected tail metric | E17: User input | F17: Does not alter the simulated distribution
A18: INSURANCE_RETENTION | B18: 0 | C18: Currency | D18: Tail loss above retention | E18: User input | F18: Indicative risk-transfer view only
A19: LEC_RETURN_PERIODS | B19: 2,5,10,20,25,50,100,200,250,500 | C19: Text | D19: AEP/OEP curve points | E19: Model setting | F19: Fixed engine-supported list

Sheet FILL OT assessment only
A1: FILL OT assessment only
A3: =IF('00 COMMON - Run Setup'!C6="OT","FILL the purple OT tabs. Ignore FILL IT.","Not used for this run.")

Sheet OT 03 - Facility Inputs
A1: 03 — Facility Inputs
A2: Purpose: Capture the facility-level unit of analysis, selected sector/asset pack, and architecture/access-route characteristics that affect exposure and TTP feasibility.
A3: =IF('00 COMMON - Run Setup'!C6="OT","FILL this sheet — OT assessment.","Not used for this run. Complete the IT assessment section only.")
A4: SHEET TYPE: USER INPUT
A5: Inputs / upstream sources
A6: Client architecture, engineering, operating model and facility information.
A7: Calculation / decision logic
A8: Facility inputs feed three mechanisms: (1) pack resolution on 28, (2) feasibility gates on 12, and (3) facility exposure on 06. Financial severity changes only through explicit BIA inputs on 05.
A9: Key assumptions / defaults
A10: The unit of analysis is one facility. Asset type must belong to the selected sector. TTPs with no explicit sector or facility gate default to applicable/feasible and remain visible for review.
A11: Outputs / downstream use
A12: Used by 06 Frequency Assumptions, 12 Facility Feasibility, 14 TTP Relevance Calc, 28–29 sector-pack sheets and the Python engine.
A13: Workbook convention: yellow cells / blue font are editable inputs or calibration assumptions; engine-output cells are not manually editable.
A15: Input | B15: Question | C15: Value | D15: Type | E15: How the model uses it | F15: Basis / evidence
A16: ASSESSMENT_ID | B16: Assessment reference | C16: PlantA | D16: Text | E16: Reporting / traceability | F16: Client
A17: ORGANISATION | B17: Organisation | C17: Example Energy Co | D17: Text | E17: Reporting | F17: Client
A18: FACILITY | B18: Facility / site | C18: Example Power Station | D18: Text | E18: Unit of analysis | F18: Client
A19: COUNTRY_REGION | B19: Country / region | C19: UAE / GCC | D19: Dropdown | E19: Actor geography multiplier | F19: Client
A20: SECTOR | B20: Sector | C20: =IF('00 COMMON - Run Setup'!C6="OT",'00 COMMON - Run Setup'!C6,"") | D20: Dropdown | E20: Actor sector multiplier + pack selection | F20: Client
A21: PLANT_TYPE | B21: Plant / asset type | C21: =IF('00 COMMON - Run Setup'!C6="OT",'00 COMMON - Run Setup'!C8,"") | D21: Dropdown (filtered by Sector) | E21: Asset-pack context and frequency overlay. List is filtered by Sector. | F21: Client
A22: CRITICAL_PROCESS | B22: Critical process / service | C22: Power generation and dispatch | D22: Text | E22: Scenario narrative / BIA scope | F22: Client
A23: IT_OT_CONNECTIVITY | B23: Enterprise IT connected to OT? | C23: Yes | D23: Dropdown | E23: Exposure multiplier + remote/IT-OT feasibility | F23: Architecture
A24: REMOTE_ACCESS | B24: Vendor / engineer remote access? | C24: Controlled | D24: Dropdown | E24: Exposure multiplier + remote TTP feasibility | F24: Architecture
A25: INTERNET_OT | B25: Critical OT service internet-accessible? | C25: No | D25: Dropdown | E25: Exposure multiplier + internet TTP feasibility | F25: Architecture
